+ source ../common_lib/fsio_lib.sh
++ source /root/mugen/libs/locallibs/common_lib.sh
+++ python3 --version
+++ '[' 0 -eq 0 ']'
+++ source /root/mugen/libs/locallibs/common_lib_python.sh
++ export 'FS_TYPE=ext3 ext4 xfs'
++ FS_TYPE='ext3 ext4 xfs'
++ export LANG=en_US.UTF-8
++ LANG=en_US.UTF-8
++ REMOVE_VG
++ vggroup=
++ [[ '' != '' ]]
+++ df -T
+++ grep test_vggroup
+++ awk '{print $7}'
++ mounted=
++ [[ '' != '' ]]
++ lsblk
++ grep test_vggroup
++ [[ 1 -eq 0 ]]
++ rm -rf /tmp/point120230428213103 /tmp/point220230428213103 /tmp/point320230428213103
+ main
++ type -t post_test
+ '[' -n function ']'
+ trap post_test EXIT INT HUP TERM
+ rpm -qa
+ grep expect
++ type -t config_params
+ '[' -n '' ']'
++ type -t pre_test
+ '[' -n function ']'
+ pre_test
+ LOG_INFO 'Start environment preparation.'
+ message='Start environment preparation.'
+ python3 /root/mugen/libs/locallibs/mugen_log.py --level info --message 'Start environment preparation.'
Fri Apr 28 21:32:13 2023 - INFO  - Start environment preparation.
++ date +%Y%m%d%H%M%S
+ cur_date=20230428213213
++ CREATE_VG
+++ date +%Y%m%d%H%M%S
++ cur_date=20230428213213
+++ lsblk
+++ grep disk
+++ awk '{print $1}'
+++ tail -n 1
++ free_disk=vdt
++ disk_name=/dev/vdt
++ pvcreate /dev/vdt -f
++ [[ 5 -eq 0 ]]
+++ pvcreate /dev/vdt
+++ cut -d '"' -f 4
+++ grep test_vggroup
++ vggroup=test_vggroup20230428204559
++ printf test_vggroup20230428204559
+ vggroup=test_vggroup20230428204559
+ ext4_point=/tmp/ext420230428213213
+ lvcreate -n test_lv120230428213213 -L 2G test_vggroup20230428204559 -y
  Volume group "test_vggroup20230428204559" has insufficient free space (124 extents): 512 required.
+ mkfs.ext4 /dev/test_vggroup20230428204559/test_lv120230428213213
mke2fs 1.46.5 (30-Dec-2021)
The file /dev/test_vggroup20230428204559/test_lv120230428213213 does not exist and no size was specified.
+ mkdir /tmp/ext420230428213213
++ ls /sys/fs/ext4
++ wc -l
+ origin=3
+ LOG_INFO 'End of environmental preparation!'
+ message='End of environmental preparation!'
+ python3 /root/mugen/libs/locallibs/mugen_log.py --level info --message 'End of environmental preparation!'
Fri Apr 28 21:32:16 2023 - INFO  - End of environmental preparation!
++ type -t run_test
+ '[' -n function ']'
+ run_test
+ LOG_INFO 'Start to run test.'
+ message='Start to run test.'
+ python3 /root/mugen/libs/locallibs/mugen_log.py --level info --message 'Start to run test.'
Fri Apr 28 21:32:17 2023 - INFO  - Start to run test.
+ mount /dev/test_vggroup20230428204559/test_lv120230428213213 /tmp/ext420230428213213
mount: /tmp/ext420230428213213: special device /dev/test_vggroup20230428204559/test_lv120230428213213 does not exist.
+ CHECK_RESULT 32 0 0 'Mount failed.'
+ actual_result=32
+ expect_result=0
+ mode=0
+ error_log='Mount failed.'
+ exit_mode=0
+ '[' -z 32 ']'
+ '[' 0 -eq 0 ']'
+ test 32x '!=' 0x
+ test -n 'Mount failed.'
+ LOG_ERROR 'Mount failed.'
+ message='Mount failed.'
+ python3 /root/mugen/libs/locallibs/mugen_log.py --level error --message 'Mount failed.'
Fri Apr 28 21:32:18 2023 - ERROR - Mount failed.
+ (( exec_result++ ))
+ LOG_ERROR 'oe_test_FSIO_sys_fs_check.sh line 36'
+ message='oe_test_FSIO_sys_fs_check.sh line 36'
+ python3 /root/mugen/libs/locallibs/mugen_log.py --level error --message 'oe_test_FSIO_sys_fs_check.sh line 36'
Fri Apr 28 21:32:19 2023 - ERROR - oe_test_FSIO_sys_fs_check.sh line 36
+ '[' 0 -eq 1 ']'
+ return 0
++ ls /sys/fs/ext4
++ wc -l
+ actual=3
+ change=0
+ CHECK_RESULT 0 1 0 'Check change failed.'
+ actual_result=0
+ expect_result=1
+ mode=0
+ error_log='Check change failed.'
+ exit_mode=0
+ '[' -z 0 ']'
+ '[' 0 -eq 0 ']'
+ test 0x '!=' 1x
+ test -n 'Check change failed.'
+ LOG_ERROR 'Check change failed.'
+ message='Check change failed.'
+ python3 /root/mugen/libs/locallibs/mugen_log.py --level error --message 'Check change failed.'
Fri Apr 28 21:32:20 2023 - ERROR - Check change failed.
+ (( exec_result++ ))
+ LOG_ERROR 'oe_test_FSIO_sys_fs_check.sh line 39'
+ message='oe_test_FSIO_sys_fs_check.sh line 39'
+ python3 /root/mugen/libs/locallibs/mugen_log.py --level error --message 'oe_test_FSIO_sys_fs_check.sh line 39'
Fri Apr 28 21:32:20 2023 - ERROR - oe_test_FSIO_sys_fs_check.sh line 39
+ '[' 0 -eq 1 ']'
+ return 0
+ LOG_INFO 'End to run test.'
+ message='End to run test.'
+ python3 /root/mugen/libs/locallibs/mugen_log.py --level info --message 'End to run test.'
Fri Apr 28 21:32:21 2023 - INFO  - End to run test.
+ CASE_RESULT 0
+ case_re=0
+ test -z 2
+ test 2 -gt 0
+ LOG_ERROR 'failed to execute the case.'
+ message='failed to execute the case.'
+ python3 /root/mugen/libs/locallibs/mugen_log.py --level error --message 'failed to execute the case.'
Fri Apr 28 21:32:22 2023 - ERROR - failed to execute the case.
+ exit 2
+ post_test
+ LOG_INFO 'Start to restore the test environment.'
+ message='Start to restore the test environment.'
+ python3 /root/mugen/libs/locallibs/mugen_log.py --level info --message 'Start to restore the test environment.'
Fri Apr 28 21:32:23 2023 - INFO  - Start to restore the test environment.
+ umount -f /tmp/ext420230428213213
umount: /tmp/ext420230428213213: not mounted.
+ LOG_INFO 'End to restore the test environment.'
+ message='End to restore the test environment.'
+ python3 /root/mugen/libs/locallibs/mugen_log.py --level info --message 'End to restore the test environment.'
Fri Apr 28 21:32:24 2023 - INFO  - End to restore the test environment.
