+ source /root/mugen/libs/locallibs/common_lib.sh
++ python3 --version
++ '[' 0 -eq 0 ']'
++ source /root/mugen/libs/locallibs/common_lib_python.sh
+ main
++ type -t post_test
+ '[' -n function ']'
+ trap post_test EXIT INT HUP TERM
+ rpm -qa
+ grep expect
++ type -t config_params
+ '[' -n '' ']'
++ type -t pre_test
+ '[' -n function ']'
+ pre_test
+ LOG_INFO 'Start to prepare the database config.'
+ message='Start to prepare the database config.'
+ python3 /root/mugen/libs/locallibs/mugen_log.py --level info --message 'Start to prepare the database config.'
Fri Apr 28 21:37:07 2023 - INFO  - Start to prepare the database config.
+ DNF_INSTALL 'libaio-devel gcc'
+ pkgs='libaio-devel gcc'
+ node=1
+ '[' -z '' ']'
+ tmpfile=
++ python3 /root/mugen/libs/locallibs/rpm_manage.py install --pkgs 'libaio-devel gcc' --node 1 --tempfile ''
+ tmpfile2=/tmp/tmpqfxorr25
+ '[' -z '' ']'
+ tmpfile=/tmp/tmpqfxorr25
+ [[ ! -f ./libaio_file ]]
+ make
In file included from /usr/include/bits/fcntl.h:62,
                 from /usr/include/fcntl.h:35,
                 from libaio_file.c:3:
/usr/include/bits/fcntl-linux.h:354:11: fatal error: linux/falloc.h: No such file or directory
  354 | # include <linux/falloc.h>
      |           ^~~~~~~~~~~~~~~~
compilation terminated.
make: *** [Makefile:4: default] Error 1
+ LOG_INFO 'End to prepare the database config.'
+ message='End to prepare the database config.'
+ python3 /root/mugen/libs/locallibs/mugen_log.py --level info --message 'End to prepare the database config.'
Fri Apr 28 21:37:43 2023 - INFO  - End to prepare the database config.
++ type -t run_test
+ '[' -n function ']'
+ run_test
+ LOG_INFO 'Start to run test.'
+ message='Start to run test.'
+ python3 /root/mugen/libs/locallibs/mugen_log.py --level info --message 'Start to run test.'
Fri Apr 28 21:37:44 2023 - INFO  - Start to run test.
+ echo test_libaio_file
+ ./libaio_file
oe_test_FSIO_aio_libaio.sh: line 32: ./libaio_file: No such file or directory
+ CHECK_RESULT 127 0 0 'libaio rw file failed.'
+ actual_result=127
+ expect_result=0
+ mode=0
+ error_log='libaio rw file failed.'
+ exit_mode=0
+ '[' -z 127 ']'
+ '[' 0 -eq 0 ']'
+ test 127x '!=' 0x
+ test -n 'libaio rw file failed.'
+ LOG_ERROR 'libaio rw file failed.'
+ message='libaio rw file failed.'
+ python3 /root/mugen/libs/locallibs/mugen_log.py --level error --message 'libaio rw file failed.'
Fri Apr 28 21:37:45 2023 - ERROR - libaio rw file failed.
+ (( exec_result++ ))
+ LOG_ERROR 'oe_test_FSIO_aio_libaio.sh line 33'
+ message='oe_test_FSIO_aio_libaio.sh line 33'
+ python3 /root/mugen/libs/locallibs/mugen_log.py --level error --message 'oe_test_FSIO_aio_libaio.sh line 33'
Fri Apr 28 21:37:46 2023 - ERROR - oe_test_FSIO_aio_libaio.sh line 33
+ '[' 0 -eq 1 ']'
+ return 0
+ grep 'test libaio' test_libaio_file
grep: test_libaio_file: No such file or directory
+ CHECK_RESULT 2 0 0 'The file infos are error.'
+ actual_result=2
+ expect_result=0
+ mode=0
+ error_log='The file infos are error.'
+ exit_mode=0
+ '[' -z 2 ']'
+ '[' 0 -eq 0 ']'
+ test 2x '!=' 0x
+ test -n 'The file infos are error.'
+ LOG_ERROR 'The file infos are error.'
+ message='The file infos are error.'
+ python3 /root/mugen/libs/locallibs/mugen_log.py --level error --message 'The file infos are error.'
Fri Apr 28 21:37:46 2023 - ERROR - The file infos are error.
+ (( exec_result++ ))
+ LOG_ERROR 'oe_test_FSIO_aio_libaio.sh line 35'
+ message='oe_test_FSIO_aio_libaio.sh line 35'
+ python3 /root/mugen/libs/locallibs/mugen_log.py --level error --message 'oe_test_FSIO_aio_libaio.sh line 35'
Fri Apr 28 21:37:47 2023 - ERROR - oe_test_FSIO_aio_libaio.sh line 35
+ '[' 0 -eq 1 ']'
+ return 0
+ LOG_INFO 'End to run test.'
+ message='End to run test.'
+ python3 /root/mugen/libs/locallibs/mugen_log.py --level info --message 'End to run test.'
Fri Apr 28 21:37:48 2023 - INFO  - End to run test.
+ CASE_RESULT 0
+ case_re=0
+ test -z 2
+ test 2 -gt 0
+ LOG_ERROR 'failed to execute the case.'
+ message='failed to execute the case.'
+ python3 /root/mugen/libs/locallibs/mugen_log.py --level error --message 'failed to execute the case.'
Fri Apr 28 21:37:49 2023 - ERROR - failed to execute the case.
+ exit 2
+ post_test
+ LOG_INFO 'Start to restore the test environment.'
+ message='Start to restore the test environment.'
+ python3 /root/mugen/libs/locallibs/mugen_log.py --level info --message 'Start to restore the test environment.'
Fri Apr 28 21:37:50 2023 - INFO  - Start to restore the test environment.
+ rm -f test_libaio_file
+ make clean
+ DNF_REMOVE
+ node=1
+ pkg_list=
+ mode=0
+ [[ -z /tmp/tmpqfxorr25 ]]
+ '[' 0 -ne 0 ']'
+ '[' 1 == 0 ']'
+ python3 /root/mugen/libs/locallibs/rpm_manage.py remove --node 1 --pkgs '' --tempfile /tmp/tmpqfxorr25
+ '[' 0 -ne 0 ']'
+ LOG_INFO 'End to restore the test environment.'
+ message='End to restore the test environment.'
+ python3 /root/mugen/libs/locallibs/mugen_log.py --level info --message 'End to restore the test environment.'
Fri Apr 28 21:38:02 2023 - INFO  - End to restore the test environment.
